<?xml version="1.0"?>

<robot xmlns:xacro="http://ros.org/wiki/xacro" name="sdvt_wheel">

	<!--<xacro:macro name="sdvt_wheel" params="wheel_prefix *joint_pose">
		<link name="${wheel_prefix}_wheel_link">
			<inertial>
				<mass value="2.637" />
				<origin xyz="0 0 0" />
				<inertia  ixx="0.02467" ixy="0" ixz="0" iyy="0.02467" iyz="0" izz="0.04411" />
			</inertial>
			<visual>
				<origin xyz="0 0 0" rpy="0 0 0" />
				<geometry>
 					<cylinder length="${wheel_length}" radius="${wheel_radius}" />
				</geometry>
			</visual>
			<collision>
				<origin xyz="0 0 0" rpy="${M_PI/2} 0 0" />
				<geometry>
					<cylinder length="${wheel_length}" radius="${wheel_radius}" />
				</geometry>
			</collision>
		</link>

		<gazebo reference="${wheel_prefix}_wheel_link">
			<mu1 value="1.0"/>
			<mu2 value="1.0"/>
			<kp value="10000000.0" />
			<kd value="1.0" />
			<fdir1 value="1 0 0"/>
		</gazebo>

		<joint name="${wheel_prefix}_wheel" type="continuous">
			<parent link="base_link"/>
			<child link="${wheel_prefix}_wheel_link"/>
			<xacro:insert_block name="joint_pose"/>
			<axis xyz="0 1 0" rpy="0 0 0" />
		</joint>

		<transmission name="${wheel_prefix}_wheel_trans" type="SimpleTransmission">
			<type>transmission_interface/SimpleTransmission</type>
			<actuator name="${wheel_prefix}_wheel_motor">
				<mechanicalReduction>1</mechanicalReduction>
			</actuator>
			<joint name="${wheel_prefix}_wheel">
				<hardwareInterface>VelocityJointInterface</hardwareInterface>
			</joint>
		</transmission>

	</xacro:macro>-->


  <xacro:property name="wheel_joint_damping" value="0.2" />
  <xacro:property name="wheel_joint_friction" value="0.7" />
  <xacro:property name="axle_eff_limit" value="204.95"/>
  <xacro:property name="axle_vel_limit" value="39.02"/>
  <xacro:property name="servo_stall_torque" value="50"/>  <!-- check -->
  <xacro:property name="servo_no_load_speed" value="25"/> <!-- check -->
  <!-- Wheel Mounting Positions -->
  <xacro:property name="wheelbase" value="1.702" />
  <xacro:property name="track" value="1.016" />
  <xacro:property name="wheel_vertical_offset" value="-0.05" />
  <!-- Degree-to-radian conversions -->
  <xacro:property name="degrees_45" value="0.785398163"/>
  <xacro:property name="degrees_90" value="1.57079633"/>
  <xacro:property name="degrees_180" value="3.14159265"/>

  <!-- Null inertial element. This is needed to make the model work with
       Gazebo. -->
  <xacro:macro name="null_inertial">
    <inertial>
      <mass value="0.001"/>
      <inertia ixx="0.001" ixy="0" ixz="0" iyy="0.001" iyz="0" izz="0.001"/>
    </inertial>
  </xacro:macro>
  <!-- The "wheel" macro defines an axle carrier, axle, and wheel. -->
  <xacro:macro name="wheel" params="lr_prefix fr_prefix lr_reflect fr_reflect ">
    
    <link name="${lr_prefix}_${fr_prefix}_axle_carrier">
      <xacro:null_inertial/>
    </link>

    <link name="${lr_prefix}_${fr_prefix}_wheel">
			<inertial>
				<mass value="2.637" />
				<origin xyz="0 0 0" />
				<inertia  ixx="0.02467" ixy="0" ixz="0" iyy="0.02467" iyz="0" izz="0.04411" />
			</inertial>
			<visual>
				<origin xyz="0 0 0" rpy="0 0 0" />
				<geometry>
 					<cylinder length="${wheel_length}" radius="${wheel_radius}" />
				</geometry>
			</visual>
			<collision>
				<origin xyz="0 0 0" rpy="${M_PI/2} 0 0" />
				<geometry>
					<cylinder length="${wheel_length}" radius="${wheel_radius}" />
				</geometry>
			</collision>
	</link>

    <!-- The left and right axles have the same axis so that identical
         rotation values cause the wheels to rotate in the same direction. -->
    <joint name="${lr_prefix}_${fr_prefix}_axle" type="continuous">
      <parent link="${lr_prefix}_${fr_prefix}_axle_carrier"/>
      <child link="${lr_prefix}_${fr_prefix}_wheel"/>
	  <axis xyz="0 0 -1" rpy="0 0 0" />
      <origin rpy="${degrees_90} 0 ${degrees_180}"/>
      <limit effort="${axle_eff_limit}" velocity="${axle_vel_limit}"/>
      <joint_properties damping="${wheel_joint_damping}" friction="{wheel_joint_friction}"/>
    </joint>
 
    <transmission name="${lr_prefix}_${fr_prefix}_axle_trans">
      <type>transmission_interface/SimpleTransmission</type>
      <joint name="${lr_prefix}_${fr_prefix}_axle">
        <hardwareInterface>VelocityJointInterface</hardwareInterface>
      </joint>
      <actuator name="${lr_prefix}_${fr_prefix}_axle_act">
        <mechanicalReduction>1</mechanicalReduction>
      </actuator>
    </transmission>

    <gazebo reference="${lr_prefix}_${fr_prefix}_axle_carrier">
      <material>Gazebo/Black</material>
    </gazebo>



    <gazebo reference="${lr_prefix}_${fr_prefix}_wheel">
      <material>Gazebo/Black</material>
    </gazebo>
  </xacro:macro>

	<!-- Front wheel -->
	<xacro:macro name="front_wheel" params="lr_prefix fr_prefix lr_reflect fr_reflect *joint_pose">
		<link name="${lr_prefix}_steering_link">
			<xacro:null_inertial/>
    	</link>
		<joint name="${lr_prefix}_front_base" type="fixed">
			<parent link="base_link"/>
			<child link="${lr_prefix}_steering_link"/>
			<axis xyz="0 0 1" rpy="0 0 0" />
		</joint>
		<joint name="${lr_prefix}_steering_joint" type="revolute">
			<parent link="base_link"/>
			<child link="${lr_prefix}_${fr_prefix}_axle_carrier"/>
			<xacro:insert_block name="joint_pose"/>
			<axis xyz="0 1 0" rpy="0 0 0" />
			<limit lower="${-degrees_45}" upper="${degrees_45}" effort="${servo_stall_torque}" velocity="${servo_no_load_speed}"/>
		</joint>
		<transmission name="${lr_prefix}_steering_trans">
			<type>transmission_interface/SimpleTransmission</type>
			<joint name="${lr_prefix}_steering_joint">
				<hardwareInterface>EffortJointInterface</hardwareInterface>
			</joint>
			<actuator name="${lr_prefix}_steering_act">
				<mechanicalReduction>1</mechanicalReduction>
			</actuator>
		</transmission>

		<!--<gazebo reference="${lr_prefix}_steering_link">
			<material>Gazebo/Black</material>
		</gazebo>-->

    	<xacro:wheel lr_prefix="${lr_prefix}" fr_prefix="${fr_prefix}" lr_reflect="${lr_reflect}" fr_reflect="${fr_reflect}"/>
	</xacro:macro>

	<!-- Rear wheel -->
	<xacro:macro name="rear_wheel" params="lr_prefix fr_prefix lr_reflect fr_reflect *joint_pose">

		<link name="${lr_prefix}_rear_link">
			<xacro:null_inertial/>
    	</link>
		<joint name="${lr_prefix}_rear_base" type="fixed">
			<parent link="base_link"/>
			<child link="${lr_prefix}_rear_link"/>
			<axis xyz="0 0 1" rpy="0 0 0" />
		</joint>
		<joint name="${lr_prefix}_rear_joint" type="fixed">
			<parent link="base_link"/>
			<child link="${lr_prefix}_${fr_prefix}_axle_carrier"/>
			<xacro:insert_block name="joint_pose"/>
			<axis xyz="0 0 1" rpy="0 0 0" />
		</joint>

		<!--<gazebo reference="${lr_prefix}_rear_link">
			<material>Gazebo/Black</material>
		</gazebo>-->
	<xacro:wheel lr_prefix="${lr_prefix}" fr_prefix="${fr_prefix}" lr_reflect="${lr_reflect}" fr_reflect="${fr_reflect}"/>
	</xacro:macro> 

</robot>
